<mujoco model="DOG">
  <compiler angle="radian" meshdir="assets/"/>

  <asset>
    <mesh name="BASE_LINK" file="BASE_LINK.STL"/>
    <mesh name="FL_ABAD_LINK" file="FL_ABAD_LINK.STL"/>
    <mesh name="FL_HIP_LINK" file="FL_HIP_LINK.STL"/>
    <mesh name="FL_KNEE_LINK" file="FL_KNEE_LINK.STL"/>
    <mesh name="FL_FOOT_LINK" file="FL_FOOT_LINK.STL"/>
    <mesh name="FR_ABAD_LINK" file="FR_ABAD_LINK.STL"/>
    <mesh name="FR_HIP_LINK" file="FR_HIP_LINK.STL"/>
    <mesh name="FR_KNEE_LINK" file="FR_KNEE_LINK.STL"/>
    <mesh name="FR_FOOT_LINK" file="FR_FOOT_LINK.STL"/>
    <mesh name="RR_ABAD_LINK" file="RR_ABAD_LINK.STL"/>
    <mesh name="RR_HIP_LINK" file="RR_HIP_LINK.STL"/>
    <mesh name="RR_KNEE_LINK" file="RR_KNEE_LINK.STL"/>
    <mesh name="RR_FOOT_LINK" file="RR_FOOT_LINK.STL"/>
    <mesh name="RL_ABAD_LINK" file="RL_ABAD_LINK.STL"/>
    <mesh name="RL_HIP_LINK" file="RL_HIP_LINK.STL"/>
    <mesh name="RL_KNEE_LINK" file="RL_KNEE_LINK.STL"/>
    <mesh name="RL_FOOT_LINK" file="RL_FOOT_LINK.STL"/>
  </asset>

  <worldbody>
    <body name="base_link" pos="0 0 0.5">
            <inertial pos="0.0050538027 -0.000631701 0.0050408732" quat="1.0 0.0 0.0 0.0"
                mass="6.7155497"
                diaginertia="0.030172666 0.088387421 0.10431072" />
            <freejoint />

    <site name="imu" pos="0.0 0 0.0" />
    <geom type="mesh" contype="0" conaffinity="0" group="1" density="0" rgba="0.75294 0.75294 0.75294 1" mesh="BASE_LINK"/>
    <geom type="mesh" rgba="0.75294 0.75294 0.75294 1" mesh="BASE_LINK"/>
    <body name="FR_ABAD_LINK" pos="0.1745 -0.062 0">
      <inertial pos="-0.0270745 0.0154588 -9.41679e-06" quat="0.373963 0.373798 0.600186 0.60017" mass="0.454098" diaginertia="0.000562658 0.000541021 0.00017585"/>
      <joint name="FAR_ABAD_JOINT" pos="0 0 0" axis="1 0 0" range="-0.4887 0.4887" actuatorfrcrange="-28 28" frictionloss="0.2"/>
      <geom type="mesh" contype="0" conaffinity="0" group="1" density="0" rgba="0.75294 0.75294 0.75294 1" mesh="FR_ABAD_LINK"/>
      <body name="FR_HIP_LINK" pos="0 -0.097399 0">
        <inertial pos="-0.00183223 0.0507983 -0.0162058" quat="0.950918 -0.305965 0.0459754 0.00523222" mass="1.34038" diaginertia="0.00561506 0.00444048 0.00201467"/>
        <joint name="FAR_HIP_JOINT" pos="0 0 0" axis="0 1 0" range="-1.152 2.967" actuatorfrcrange="-28 28"  frictionloss="0.2"/>
        <geom type="mesh" contype="0" conaffinity="0" group="1" density="0" rgba="0.75294 0.4 0.75294 1" mesh="FR_HIP_LINK"/>
        <geom size="0.02 0.01 0.09" pos="-0.01 0 -0.06" quat="0.995004 0 0.0998334 0" type="box" rgba="0.75294 0.4 0.75294 1"/>
        <body name="FR_KNEE_LINK" pos="0 0 -0.2">
          <inertial pos="0.00294408 0.010162 -0.183997" quat="0.756861 0.0354504 -0.0109883 0.652522" mass="0.765109" diaginertia="0.00439972 0.00433169 0.000401184"/>
          <joint name="FAR_KNEE_JOINT" pos="0 0 0" axis="0 1 0" range="-2.723 -0.602" actuatorfrcrange="-28 28"  frictionloss="0.2"/>
          <geom type="mesh" contype="0" conaffinity="0" group="1" density="0" rgba="0.49804 0.5 0.49804 1" mesh="FR_KNEE_LINK"/>
          <geom size="0.01 0.01 0.055" pos="0.021 0 -0.06" quat="0.995953 0 -0.0898785 0" type="box" rgba="0.49804 0.5 0.49804 1"/>
          <body name="FR_FOOT_LINK" pos="0 0 -0.21366">
            <inertial pos="0 -0.0448803 0" quat="0.5 0.5 0.5 0.5" mass="0.901304" diaginertia="0.0024723 0.00142858 0.00142854"/>
            <joint name="FAR_FOOT_JOINT" pos="0 0 0" axis="0 1 0" range="-999999 999999" actuatorfrcrange="-28 28" />
            <geom type="mesh" contype="0" conaffinity="0" group="1" density="0" rgba="0.75294 0.6 0.75294 1" mesh="FR_FOOT_LINK"/> 
            <geom type="mesh" rgba="0.75294 0.6 0.75294 1" mesh="FR_FOOT_LINK"/>
          </body>
        </body>
      </body>
    </body>
    <body name="FL_ABAD_LINK" pos="0.17449 0.062 0">
      <inertial pos="-0.0270745 -0.0154588 9.41679e-06" quat="0.600186 0.60017 0.373963 0.373798" mass="0.454098" diaginertia="0.000562658 0.000541021 0.00017585"/>
      <joint name="FBL_ABAD_JOINT" pos="0 0 0" axis="1 0 0" range="-0.4887 0.4887" actuatorfrcrange="-28 28" frictionloss="0.2"/>
      <geom type="mesh" contype="0" conaffinity="0" group="1" density="0" rgba="0.75294 0.75294 0.2 1" mesh="FL_ABAD_LINK"/>
      <body name="FL_HIP_LINK" pos="0 0.097412 0">
        <inertial pos="-0.00183223 -0.0507983 -0.0162058" quat="0.950918 0.305965 0.0459754 -0.00523222" mass="1.34038" diaginertia="0.00561506 0.00444048 0.00201467"/>
        <joint name="FBL_HIP_JOINT" pos="0 0 0" axis="0 1 0" range="-1.152 2.967" actuatorfrcrange="-28 28" frictionloss="0.2"/>
        <geom type="mesh" contype="0" conaffinity="0" group="1" density="0" rgba="0.4 0.75294 0.75294 1" mesh="FL_HIP_LINK"/>
        <geom size="0.02 0.01 0.09" pos="-0.01 0 -0.06" quat="0.995004 0 0.0998334 0" type="box" rgba="0.75294 0.75294 0.75294 1"/>
        <body name="FL_KNEE_LINK" pos="0 0 -0.2">
          <inertial pos="0.00296222 -0.010162 -0.184008" quat="0.655839 -0.011223 0.0353855 0.753988" mass="0.765108" diaginertia="0.0044001 0.00433244 0.000401077"/>
          <joint name="FBL_KNEE_JOINT" pos="0 0 0" axis="0 1 0" range="-2.723 -0.602" actuatorfrcrange="-28 28" frictionloss="0.2"/>
          <geom type="mesh" contype="0" conaffinity="0" group="1" density="0" rgba="0.79216 0.81961 0.93333 1" mesh="FL_KNEE_LINK"/>
          <geom size="0.01 0.01 0.055" pos="0.021 0 -0.06" quat="0.995953 0 -0.0898785 0" type="box" rgba="0.49804 0.49804 0.49804 1"/>
          <body name="FL_FOOT_LINK" pos="0 0 -0.21366">
            <inertial pos="0 0.0448803 0" quat="0.5 0.5 0.5 0.5" mass="0.901304" diaginertia="0.0024723 0.00142858 0.00142854"/>
            <joint name="FBL_FOOT_JOINT" pos="0 0 0" axis="0 1 0" range="-999999 999999" actuatorfrcrange="-28 28" />
            <geom type="mesh" contype="0" conaffinity="0" group="1" density="0" rgba="0.6 0.75294 0.75294 1" mesh="FL_FOOT_LINK"/>
            <geom type="mesh" rgba="0.6 0.75294 0.75294 1" mesh="FL_FOOT_LINK"/>
          </body>
        </body>
      </body>
    </body>
    <body name="RR_ABAD_LINK" pos="-0.1745 -0.062 0">
      <inertial pos="0.0270745 0.0154588 9.41679e-06" quat="0.60017 0.600186 0.373798 0.373963" mass="0.454098" diaginertia="0.000562658 0.000541021 0.00017585"/>
      <joint name="RAR_ABAD_JOINT" pos="0 0 0" axis="1 0 0" range="-0.4887 0.4887" actuatorfrcrange="-28 28" frictionloss="0.2"/>
      <geom type="mesh" contype="0" conaffinity="0" group="1" density="0" rgba="0.75294 0.2 0.75294 1" mesh="RR_ABAD_LINK"/>
      <body name="RR_HIP_LINK" pos="0 -0.09735 0">
        <inertial pos="-0.00183223 0.0507983 -0.0162058" quat="0.950918 -0.305965 0.0459754 0.00523222" mass="1.34038" diaginertia="0.00561506 0.00444048 0.00201467"/>
        <joint name="RAR_HIP_JOINT" pos="0 0 0" axis="0 1 0" range="-1.152 2.967" actuatorfrcrange="-28 28" frictionloss="0.2"/>
        <geom type="mesh" contype="0" conaffinity="0" group="1" density="0" rgba="0.75294 0.75294 0.4 1" mesh="RR_HIP_LINK"/>
        <geom size="0.02 0.01 0.09" pos="-0.01 0 -0.06" quat="0.995004 0 0.0998334 0" type="box" rgba="0.75294 0.75294 0.4 1"/>
        <body name="RR_KNEE_LINK" pos="0 0 -0.2">
          <inertial pos="0.00294408 0.010162 -0.183997" quat="0.756861 0.0354504 -0.0109883 0.652522" mass="0.765109" diaginertia="0.00439972 0.00433169 0.000401184"/>
          <joint name="RAR_KNEE_JOINT" pos="0 0 0" axis="0 1 0" range="-2.723 -0.602" actuatorfrcrange="-28 28" frictionloss="0.2"/>
          <geom type="mesh" contype="0" conaffinity="0" group="1" density="0" rgba="0.79216 0.81961 0.5 1" mesh="RR_KNEE_LINK"/>
          <geom size="0.01 0.01 0.055" pos="0.021 0 -0.06" quat="0.995953 0 -0.0898785 0" type="box" rgba="0.79216 0.81961 0.5 1"/>
          <body name="RR_FOOT_LINK" pos="0 0 -0.21366">
            <inertial pos="0 -0.0448803 0" quat="0.5 0.5 0.5 0.5" mass="0.901304" diaginertia="0.0024723 0.00142858 0.00142854"/>
            <joint name="RAR_FOOT_JOINT" pos="0 0 0" axis="0 1 0" range="-999999 999999" actuatorfrcrange="-28 28" frictionloss="0.2"/>
            <geom type="mesh" contype="0" conaffinity="0" group="1" density="0" rgba="0.75294 0.75294 0.6 1" mesh="RR_FOOT_LINK"/>
            <geom type="mesh" rgba="0.75294 0.75294 0.6 1" mesh="RR_FOOT_LINK"/>
          </body>
        </body>
      </body>
    </body>
    <body name="RL_ABAD_LINK" pos="-0.1745 0.062 0">
      <inertial pos="0.0270745 -0.0154588 -9.41679e-06" quat="0.373798 0.373963 0.60017 0.600186" mass="0.454098" diaginertia="0.000562658 0.000541021 0.00017585"/>
      <joint name="RBL_ABAD_JOINT" pos="0 0 0" axis="1 0 0" range="-0.4887 0.4887" actuatorfrcrange="-28 28" frictionloss="0.2"/>
      <geom type="mesh" contype="0" conaffinity="0" group="1" density="0" rgba="0.5 1 1 1" mesh="RL_ABAD_LINK"/>
      <body name="RL_HIP_LINK" pos="0 0.09735 0">
        <inertial pos="-0.00183223 -0.0507983 -0.0162058" quat="0.950918 0.305965 0.0459754 -0.00523222" mass="1.34038" diaginertia="0.00561506 0.00444048 0.00201467"/>
        <joint name="RBL_HIP_JOINT" pos="0 0 0" axis="0 1 0" range="-1.152 2.967" actuatorfrcrange="-28 28" frictionloss="0.2"/>
        <geom type="mesh" contype="0" conaffinity="0" group="1" density="0" rgba="0.75294 0.75294 0.75294 0.4" mesh="RL_HIP_LINK"/>
        <geom size="0.02 0.01 0.09" pos="-0.01 0 -0.06" quat="0.995004 0 0.0998334 0" type="box" rgba="0.75294 0.75294 0.75294 0.4"/>
        <body name="RL_KNEE_LINK" pos="0 0 -0.2">
          <inertial pos="0.00296222 -0.010162 -0.184008" quat="0.655839 -0.011223 0.0353855 0.753988" mass="0.765108" diaginertia="0.0044001 0.00433244 0.000401077"/>
          <joint name="RBL_KNEE_JOINT" pos="0 0 0" axis="0 1 0" range="-2.723 -0.602" actuatorfrcrange="-28 28" frictionloss="0.2"/>
          <geom type="mesh" contype="0" conaffinity="0" group="1" density="0" rgba="0.49804 0.49804 0.49804 0.4" mesh="RL_KNEE_LINK"/>
          <geom size="0.01 0.01 0.055" pos="0.021 0 -0.06" quat="0.995953 0 -0.0898785 0" type="box" rgba="0.49804 0.49804 0.49804 0.4"/>
          <body name="RL_FOOT_LINK" pos="0 0 -0.21366">
            <inertial pos="0 0.0448803 0" quat="0.5 0.5 0.5 0.5" mass="0.901304" diaginertia="0.0024723 0.00142858 0.00142854"/>
            <joint name="RBL_FOOT_JOINT" pos="0 0 0" axis="0 1 0" range="-999999 999999" actuatorfrcrange="-28 28" frictionloss="0.2"/>
            <geom type="mesh" contype="0" conaffinity="0" group="1" density="0" rgba="0.75294 0.75294 0.75294 0.6" mesh="RL_FOOT_LINK"/>
            <geom type="mesh" rgba="0.75294 0.75294 0.75294 0.6" mesh="RL_FOOT_LINK"/>
          </body>
          </body>
        </body>
      </body>
    </body>
  </worldbody>

  <actuator>
        <motor name="FR_ABAD_LINK" joint="FAR_ABAD_JOINT" />
        <motor name="FR_HIP_LINK" joint="FAR_HIP_JOINT" />
        <motor name="FR_KNEE_LINK" joint="FAR_KNEE_JOINT" />
        <motor name="FR_FOOT_LINK" joint="FAR_FOOT_JOINT" />
        <motor name="FL_ABAD_LINK" joint="FBL_ABAD_JOINT" />
        <motor name="FL_HIP_LINK" joint="FBL_HIP_JOINT" />
        <motor name="FL_KNEE_LINK" joint="FBL_KNEE_JOINT" />
        <motor name="FL_FOOT_LINK" joint="FBL_FOOT_JOINT" />
        <motor name="RR_ABAD_LINK" joint="RAR_ABAD_JOINT" />
        <motor name="RR_HIP_LINK" joint="RAR_HIP_JOINT" />
        <motor name="RR_KNEE_LINK" joint="RAR_KNEE_JOINT" />
        <motor name="RR_FOOT_LINK" joint="RAR_FOOT_JOINT" />
        <motor name="RL_ABAD_LINK" joint="RBL_ABAD_JOINT" />
        <motor name="RL_HIP_LINK" joint="RBL_HIP_JOINT" />
        <motor name="RL_KNEE_LINK" joint="RBL_KNEE_JOINT" />
        <motor name="RL_FOOT_LINK" joint="RBL_FOOT_JOINT" />      
    </actuator>

    <sensor>
        <jointpos name="FR_hip_pos" joint="FAR_ABAD_JOINT" />
        <jointpos name="FR_thigh_pos" joint="FAR_HIP_JOINT" />
        <jointpos name="FR_calf_pos" joint="FAR_KNEE_JOINT" />
        <jointpos name="FR_foot_pos" joint="FAR_FOOT_JOINT" />
        <jointpos name="FL_hip_pos" joint="FBL_ABAD_JOINT" />
        <jointpos name="FL_thigh_pos" joint="FBL_HIP_JOINT" />
        <jointpos name="FL_calf_pos" joint="FBL_KNEE_JOINT" />
        <jointpos name="FL_foot_pos" joint="FBL_FOOT_JOINT" />
        <jointpos name="RR_hip_pos" joint="RAR_ABAD_JOINT" />
        <jointpos name="RR_thigh_pos" joint="RAR_HIP_JOINT" />
        <jointpos name="RR_calf_pos" joint="RAR_KNEE_JOINT" />
        <jointpos name="RR_foot_pos" joint="RAR_FOOT_JOINT" />
        <jointpos name="RL_hip_pos" joint="RBL_ABAD_JOINT" />
        <jointpos name="RL_thigh_pos" joint="RBL_HIP_JOINT" />
        <jointpos name="RL_calf_pos" joint="RBL_KNEE_JOINT" />
        <jointpos name="RL_foot_pos" joint="RBL_FOOT_JOINT" />

        <jointvel name="FR_hip_vel" joint="FAR_ABAD_JOINT" />
        <jointvel name="FR_thigh_vel" joint="FAR_HIP_JOINT" />
        <jointvel name="FR_calf_vel" joint="FAR_KNEE_JOINT" />
        <jointvel name="FR_foot_vel" joint="FAR_FOOT_JOINT" />      
        <jointvel name="FL_hip_vel" joint="FBL_ABAD_JOINT" />
        <jointvel name="FL_thigh_vel" joint="FBL_HIP_JOINT" />
        <jointvel name="FL_calf_vel" joint="FBL_KNEE_JOINT" />
        <jointvel name="FL_foot_vel" joint="FBL_FOOT_JOINT" />
        <jointvel name="RR_hip_vel" joint="RAR_ABAD_JOINT" />
        <jointvel name="RR_thigh_vel" joint="RAR_HIP_JOINT" />
        <jointvel name="RR_calf_vel" joint="RAR_KNEE_JOINT" />
        <jointvel name="RR_foot_vel" joint="RAR_FOOT_JOINT" />
        <jointvel name="RL_hip_vel" joint="RBL_ABAD_JOINT" />
        <jointvel name="RL_thigh_vel" joint="RBL_HIP_JOINT" />
        <jointvel name="RL_calf_vel" joint="RBL_KNEE_JOINT" />
        <jointvel name="RL_foot_vel" joint="RBL_FOOT_JOINT" />

        <jointactuatorfrc name="FR_hip_torque" joint="FAR_ABAD_JOINT" noise="0.00" />
        <jointactuatorfrc name="FR_thigh_torque" joint="FAR_HIP_JOINT" noise="0.00" />
        <jointactuatorfrc name="FR_calf_torque" joint="FAR_KNEE_JOINT" noise="0.00" />
        <jointactuatorfrc name="FR_foot_torque" joint="FAR_FOOT_JOINT" noise="0.00" />       
        <jointactuatorfrc name="FL_hip_torque" joint="FBL_ABAD_JOINT" noise="0.00" />
        <jointactuatorfrc name="FL_thigh_torque" joint="FBL_HIP_JOINT" noise="0.00" />
        <jointactuatorfrc name="FL_calf_torque" joint="FBL_KNEE_JOINT" noise="0.00" />
        <jointactuatorfrc name="FL_foot_torque" joint="FBL_FOOT_JOINT" noise="0.00" />
        <jointactuatorfrc name="RR_hip_torque" joint="RAR_ABAD_JOINT" noise="0.00" />
        <jointactuatorfrc name="RR_thigh_torque" joint="RAR_HIP_JOINT" noise="0.00" />
        <jointactuatorfrc name="RR_calf_torque" joint="RAR_KNEE_JOINT" noise="0.00" />
        <jointactuatorfrc name="RR_foot_torque" joint="RAR_FOOT_JOINT" noise="0.00" />
        <jointactuatorfrc name="RL_hip_torque" joint="RBL_ABAD_JOINT" noise="0.00" />
        <jointactuatorfrc name="RL_thigh_torque" joint="RBL_HIP_JOINT" noise="0.00" />
        <jointactuatorfrc name="RL_calf_torque" joint="RBL_KNEE_JOINT" noise="0.00" />
        <jointactuatorfrc name="RL_foot_torque" joint="RBL_FOOT_JOINT" noise="0.00" />

        <framequat name="imu_quat" objtype="site" objname="imu" />
        <gyro name="imu_gyro" site="imu" />
        <accelerometer name="imu_acc" site="imu" />

        <framepos name="frame_pos" objtype="site" objname="imu" />
        <framelinvel name="frame_vel" objtype="site" objname="imu" />
    </sensor>

    <keyframe>
        <key name="home" qpos="0 0 0.27 1 0 0 0 0 0.9 -1.8 0 0 0.9 -1.8 0 0 0.9 -1.8 0 0 0.9 -1.8 0"
            ctrl="0 0.9 -1.8 0 0 0.9 -1.8 0 0 0.9 -1.8 0 0 0.9 -1.8 0" />
    </keyframe>
</mujoco>
