<mujoco model="Lite3">
  <compiler angle="radian" meshdir="assets/"/>

  <asset>
    <material name="gray" rgba="0.671705 0.692426 0.774270 1" />
    <mesh name="torso" file="torso.STL"/>
    <mesh name="fl_hip" file="fl_hip.STL"/>
    <mesh name="fl_thigh" file="fl_thigh.STL"/>
    <mesh name="fl_shank_collision" file="fl_shank_collision.STL"/>
    <mesh name="fr_hip" file="fr_hip.STL"/>
    <mesh name="fr_thigh" file="fr_thigh.STL"/>
    <mesh name="fr_shank_collision" file="fr_shank_collision.STL"/>
    <mesh name="hl_hip" file="hl_hip.STL"/>
    <mesh name="hl_thigh" file="hl_thigh.STL"/>
    <mesh name="hl_shank_collision" file="hl_shank_collision.STL"/>
    <mesh name="hr_hip" file="hr_hip.STL"/>
    <mesh name="hr_thigh" file="hr_thigh.STL"/>
    <mesh name="hr_shank_collision" file="hr_shank_collision.STL"/>
  </asset>

  <worldbody>
    <body name="base_link" pos="0 0 0.45">
            <inertial pos="0.0 0.0 0.0" quat="1.0 0.0 0.0 0.0"
                mass="5.6056"
                diaginertia="0.02456 0.05518 0.07016" />
            <freejoint />

    <site name="imu" pos="0.0 0 0.0" />
    <geom type="mesh" contype="0" conaffinity="0" group="1" density="0" rgba="1 1 1 1" mesh="torso"/>
    <geom type="mesh" rgba="1 1 1 1" mesh="torso"/>
    <body name="FL_HIP" pos="0.1745 0.062 0">
      <inertial pos="-0.00601 -0.0066532 0.00034295" quat="0 0.707107 0 0.707107" mass="0.55" diaginertia="0.0004472 0.0004028 0.0003949"/>
      <joint name="FL_HipX_joint" pos="0 0 0" axis="-1 0 0" range="-0.523 0.523" actuatorfrcrange="-30 30" frictionloss="0.2"/>
      <geom type="mesh" contype="0" conaffinity="0" group="1" density="0" rgba="1 1 1 1" mesh="fl_hip"/>
      <body name="FL_THIGH" pos="0 0.09735 0">
        <inertial pos="-0.0052817 -0.014632 -0.042672" mass="0.86" diaginertia="0.005736 0.00496 0.001436"/>
        <joint name="FL_HipY_joint" pos="0 0 0" axis="0 -1 0" range="-3.5 2.0" actuatorfrcrange="-30 30" frictionloss="0.2"/>
        <geom type="mesh" contype="0" conaffinity="0" group="1" density="0" rgba="1 1 1 1" mesh="fl_thigh"/>
        <geom size="0.01 0.01 0.08" pos="0 0 -0.08" type="box" rgba="1 1 1 1"/>
        <body name="FL_SHANK" pos="0 0 -0.2">
          <inertial pos="0.00573034 -1.28547e-06 -0.131807" quat="0.707101 0.00359881 0.00359725 0.707095" mass="0.173" diaginertia="0.00104615 0.00102919 3.19053e-05"/>
          <joint name="FL_Knee_joint" pos="0 0 0" axis="0 -1 0" range="0.524 2.792" actuatorfrcrange="-30 30" frictionloss="0.2"/>
          <geom type="mesh" contype="0" conaffinity="0" group="1" density="0" rgba="1 1 1 1" mesh="fl_shank_collision"/>
          <geom size="0.01 0.01 0.09" pos="0 0 -0.09" type="box" rgba="1 1 1 1"/>
          <geom size="0.022" pos="0 0 -0.21012" quat="0.707107 0.707107 0 0"/>
          <geom size="0.022" pos="0 0 -0.21012" contype="0" conaffinity="0" group="1" density="0" rgba="1 1 1 1"/>
        </body>
      </body>
     </body>
    <body name="FR_HIP" pos="0.1745 -0.062 0">
      <inertial pos="-0.010579 0.011358 0.00048546" mass="0.55" diaginertia="0.0004472 0.0004028 0.0003949"/>
      <joint name="FR_HipX_joint" pos="0 0 0" axis="-1 0 0" range="-0.523 0.523" actuatorfrcrange="-30 30" frictionloss="0.2"/>
      <geom type="mesh" contype="0" conaffinity="0" group="1" density="0" rgba="1 1 1 1" mesh="fr_hip"/>
      <body name="FR_THIGH" pos="0 -0.09735 0">
        <inertial pos="-0.0039245 0.025256 -0.025146" mass="0.86" diaginertia="0.005736 0.00496 0.001436"/>
        <joint name="FR_HipY_joint" pos="0 0 0" axis="0 -1 0" range="-3.5 2.0" actuatorfrcrange="-30 30" frictionloss="0.2"/>
        <geom type="mesh" contype="0" conaffinity="0" group="1" density="0" rgba="1 1 1 1" mesh="fr_thigh"/>
        <geom size="0.01 0.01 0.08" pos="0 0 -0.08" type="box" rgba="1 1 1 1"/>
        <body name="FR_SHANK" pos="0 0 -0.2">
          <inertial pos="0.00573034 -1.28697e-06 -0.131807" quat="0.707101 0.00359881 0.00359725 0.707095" mass="0.173" diaginertia="0.00104615 0.00102919 3.19053e-05"/>
          <joint name="FR_Knee_joint" pos="0 0 0" axis="0 -1 0" range="0.524 2.792" actuatorfrcrange="-30 30" frictionloss="0.2"/>
          <geom type="mesh" contype="0" conaffinity="0" group="1" density="0" rgba="1 1 1 1" mesh="fr_shank_collision"/>
          <geom size="0.01 0.01 0.09" pos="0 0 -0.09" type="box" rgba="1 1 1 1"/>
          <geom size="0.022" pos="0 0 -0.21012" quat="0.707107 0.707107 0 0"/>
          <geom size="0.022" pos="0 0 -0.21012" contype="0" conaffinity="0" group="1" density="0" rgba="1 1 1 1"/>
        </body>
      </body>
    </body>
    <body name="HL_HIP" pos="-0.1745 0.062 0">
      <inertial pos="0.010905 -0.012636 0.001051" quat="0 0.707107 0 0.707107" mass="0.55" diaginertia="0.0004472 0.0004028 0.0003949"/>
      <joint name="HL_HipX_joint" pos="0 0 0" axis="-1 0 0" range="-0.523 0.523" actuatorfrcrange="-30 30" frictionloss="0.2"/>
      <geom type="mesh" contype="0" conaffinity="0" group="1" density="0" rgba="1 1 1 1" mesh="hl_hip"/>
      <body name="HL_THIGH" pos="0 0.09735 0">
        <inertial pos="-0.0057137 -0.014631 -0.042453" mass="0.86" diaginertia="0.005736 0.00496 0.001436"/>
        <joint name="HL_HipY_joint" pos="0 0 0" axis="0 -1 0" range="-3.5 2.0" actuatorfrcrange="-30 30" frictionloss="0.2"/>
        <geom type="mesh" contype="0" conaffinity="0" group="1" density="0" rgba="1 1 1 1" mesh="hl_thigh"/>
        <geom size="0.01 0.01 0.08" pos="0 0 -0.08" type="box" rgba="1 1 1 1"/>
        <body name="HL_SHANK" pos="0 0 -0.2">
          <inertial pos="0.00573034 -1.2875e-06 -0.131807" quat="0.707101 0.00359881 0.00359725 0.707095" mass="0.173" diaginertia="0.00104615 0.00102919 3.19053e-05"/>
          <joint name="HL_Knee_joint" pos="0 0 0" axis="0 -1 0" range="0.524 2.792" actuatorfrcrange="-30 30" frictionloss="0.2"/>
          <geom type="mesh" contype="0" conaffinity="0" group="1" density="0" rgba="1 1 1 1" mesh="hl_shank_collision"/>
          <geom size="0.01 0.01 0.09" pos="0 0 -0.09" type="box" rgba="1 1 1 1"/>
          <geom size="0.022" pos="0 0 -0.21012" quat="0.707107 0.707107 0 0"/>
          <geom size="0.022" pos="0 0 -0.21012" contype="0" conaffinity="0" group="1" density="0" rgba="1 1 1 1"/>
        </body>
      </body>
    </body>
    <body name="HR_HIP" pos="-0.1745 -0.062 0">
      <inertial pos="0.010354 0.011423 0.00049498" quat="0 0.707107 0 0.707107" mass="0.55" diaginertia="0.0004472 0.0004028 0.0003949"/>
      <joint name="HR_HipX_joint" pos="0 0 0" axis="-1 0 0" range="-0.523 0.523" actuatorfrcrange="-30 30" frictionloss="0.2"/>
      <geom type="mesh" contype="0" conaffinity="0" group="1" density="0" rgba="1 1 1 1" mesh="hr_hip"/>
      <body name="HR_THIGH" pos="0 -0.09735 0">
        <inertial pos="-0.0031903 0.02526 -0.025617" mass="0.86" diaginertia="0.005736 0.00496 0.001436"/>
        <joint name="HR_HipY_joint" pos="0 0 0" axis="0 -1 0" range="-3.5 2.0" actuatorfrcrange="-30 30" frictionloss="0.2"/>
        <geom type="mesh" contype="0" conaffinity="0" group="1" density="0" rgba="1 1 1 1" mesh="hr_thigh"/>
        <geom size="0.01 0.01 0.08" pos="0 0 -0.08" type="box" rgba="1 1 1 1"/>
        <body name="HR_SHANK" pos="0 0 -0.2">
          <inertial pos="0.00573034 -1.28493e-06 -0.131807" quat="0.707101 0.00359881 0.00359725 0.707095" mass="0.173" diaginertia="0.00104615 0.00102919 3.19053e-05"/>
          <joint name="HR_Knee_joint" pos="0 0 0" axis="0 -1 0" range="0.524 2.792" actuatorfrcrange="-30 30" frictionloss="0.2"/>
          <geom type="mesh" contype="0" conaffinity="0" group="1" density="0" rgba="1 1 1 1" mesh="hr_shank_collision"/>
          <geom size="0.01 0.01 0.09" pos="0 0 -0.09" type="box" rgba="1 1 1 1"/>
          <geom size="0.022" pos="0 0 -0.21012" quat="0.707107 0.707107 0 0"/>
          <geom size="0.022" pos="0 0 -0.21012" contype="0" conaffinity="0" group="1" density="0" rgba="1 1 1 1"/>
        </body>
      </body>
    </body>
  </body>
  </worldbody>

  <actuator>
        <motor name="FL_HIP" joint="FL_HipX_joint" />
        <motor name="FL_THIGH" joint="FL_HipY_joint" />
        <motor name="FL_SHANK" joint="FL_Knee_joint" />
        <motor name="FR_HIP" joint="FR_HipX_joint" />
        <motor name="FR_THIGH" joint="FR_HipY_joint" />
        <motor name="FR_SHANK" joint="FR_Knee_joint" />
        <motor name="HL_HIP" joint="HL_HipX_joint" />
        <motor name="HL_THIGH" joint="HL_HipY_joint" />
        <motor name="HL_SHANK" joint="HL_Knee_joint" />
        <motor name="HR_HIP" joint="HR_HipX_joint" />
        <motor name="HR_THIGH" joint="HR_HipY_joint" />
        <motor name="HR_SHANK" joint="HR_Knee_joint" />
    </actuator>

    <sensor>
        <jointpos name="FL_hip_pos" joint="FL_HipX_joint" />
        <jointpos name="FL_thigh_pos" joint="FL_HipY_joint" />
        <jointpos name="FL_calf_pos" joint="FL_Knee_joint" />
        <jointpos name="FR_hip_pos" joint="FR_HipX_joint" />
        <jointpos name="FR_thigh_pos" joint="FR_HipY_joint" />
        <jointpos name="FR_calf_pos" joint="FR_Knee_joint" />
        <jointpos name="RL_hip_pos" joint="HL_HipX_joint" />
        <jointpos name="RL_thigh_pos" joint="HL_HipY_joint" />
        <jointpos name="RL_calf_pos" joint="HL_Knee_joint" />
        <jointpos name="RR_hip_pos" joint="HR_HipX_joint" />
        <jointpos name="RR_thigh_pos" joint="HR_HipY_joint" />
        <jointpos name="RR_calf_pos" joint="HR_Knee_joint" />
       
        <jointvel name="FL_hip_vel" joint="FL_HipX_joint" />
        <jointvel name="FL_thigh_vel" joint="FL_HipY_joint" />
        <jointvel name="FL_calf_vel" joint="FL_Knee_joint" />
        <jointvel name="FR_hip_vel" joint="FR_HipX_joint" />
        <jointvel name="FR_thigh_vel" joint="FR_HipY_joint" />
        <jointvel name="FR_calf_vel" joint="FR_Knee_joint" />
        <jointvel name="RL_hip_vel" joint="HL_HipX_joint" />
        <jointvel name="RL_thigh_vel" joint="HL_HipY_joint" />
        <jointvel name="RL_calf_vel" joint="HL_Knee_joint" />
        <jointvel name="RR_hip_vel" joint="HR_HipX_joint" />
        <jointvel name="RR_thigh_vel" joint="HR_HipY_joint" />
        <jointvel name="RR_calf_vel" joint="HR_Knee_joint" />
        
        <jointactuatorfrc name="FL_hip_torque" joint="FL_HipX_joint" noise="0.00" />
        <jointactuatorfrc name="FL_thigh_torque" joint="FL_HipY_joint" noise="0.00" />
        <jointactuatorfrc name="FL_calf_torque" joint="FL_Knee_joint" noise="0.00" />
        <jointactuatorfrc name="FR_hip_torque" joint="FR_HipX_joint" noise="0.00" />
        <jointactuatorfrc name="FR_thigh_torque" joint="FR_HipY_joint" noise="0.00" />
        <jointactuatorfrc name="FR_calf_torque" joint="FR_Knee_joint" noise="0.00" />
        <jointactuatorfrc name="RL_hip_torque" joint="HL_HipX_joint" noise="0.00" />
        <jointactuatorfrc name="RL_thigh_torque" joint="HL_HipY_joint" noise="0.00" />
        <jointactuatorfrc name="RL_calf_torque" joint="HL_Knee_joint" noise="0.00" />
        <jointactuatorfrc name="RR_hip_torque" joint="HR_HipX_joint" noise="0.00" />
        <jointactuatorfrc name="RR_thigh_torque" joint="HR_HipY_joint" noise="0.00" />
        <jointactuatorfrc name="RR_calf_torque" joint="HR_Knee_joint" noise="0.00" />
       

        <framequat name="imu_quat" objtype="site" objname="imu" />
        <gyro name="imu_gyro" site="imu" />
        <accelerometer name="imu_acc" site="imu" />

        <framepos name="frame_pos" objtype="site" objname="imu" />
        <framelinvel name="frame_vel" objtype="site" objname="imu" />
    </sensor>

    <keyframe>
        <key name="home" qpos="0 0 0.27 1 0 0 0 0 0.9 -1.8 0 0.9 -1.8 0 0.9 -1.8 0 0.9 -1.8"
            ctrl="0 -0.9 1.8 0 -0.9 1.8 0 -0.9 1.8 0 -0.9 1.8" />
    </keyframe>
</mujoco>
