<mujoco model="XG">
  <compiler angle="radian" meshdir="assets" autolimits="true" />
  <asset>
    <mesh name="base_link" file="base_link.STL" />
    <mesh name="LF_abad_link" file="LF_abad_link.STL" />
    <mesh name="LF_hip_link" file="LF_hip_link.STL" />
    <mesh name="LF_calf_link" file="LF_calf_link.STL" />
    <mesh name="LF_foot_link" file="LF_foot_link.STL" />
    <mesh name="RF_abad_link" file="RF_abad_link.STL" />
    <mesh name="RF_hip_link" file="RF_hip_link.STL" />
    <mesh name="RF_calf_link" file="RF_calf_link.STL" />
    <mesh name="RF_foot_link" file="RF_foot_link.STL" />
    <mesh name="RB_abad_link" file="RB_abad_link.STL" />
    <mesh name="RB_hip_link" file="RB_hip_link.STL" />
    <mesh name="RB_calf_link" file="RB_calf_link.STL" />
    <mesh name="RB_foot_link" file="RB_foot_link.STL" />
    <mesh name="LB_abad_link" file="LB_abad_link.STL" />
    <mesh name="LB_hip_link" file="LB_hip_link.STL" />
    <mesh name="LB_calf_link" file="LB_calf_link.STL" />
    <mesh name="LB_foot_link" file="LB_foot_link.STL" />
  </asset>

  <worldbody>
    <geom type="mesh" rgba="0.752941 0.752941 0.752941 1" mesh="base_link" />
    <body name="LF_abad_link" pos="0.1941 0.04 0">
      <inertial pos="-0.00266655 0.013352 4.41673e-05"
        quat="0.708219 -0.00527067 -0.00425517 0.70596" mass="0.99188"
        diaginertia="0.00125474 0.000735478 0.000688757" />
      <joint name="LF_abad_joint" pos="0 0 0" axis="1 0 0" />
      <geom type="mesh" rgba="0.752941 0.752941 0.752941 1" mesh="LF_abad_link" />
      <body name="LF_hip_link" pos="0 0.0666 0">
        <inertial pos="-0.00125195 0.0194981 -0.0144633"
          quat="0.707714 -0.00704778 -0.0180221 0.706234" mass="1.29793"
          diaginertia="0.00279985 0.00204322 0.000920557" />
        <joint name="LF_hip_joint" pos="0 0 0" axis="0 1 0" />
        <geom type="mesh" rgba="0.752941 0.752941 0.752941 1" mesh="LF_hip_link" />
        <body name="LF_calf_link" pos="0 0.0485 -0.213">
          <inertial pos="0.00999248 1.00893e-07 -0.119967"
            quat="0.706696 0.023841 0.0238376 0.706714" mass="0.494625"
            diaginertia="0.00267497 0.0026374 0.000100791" />
          <joint name="LF_calf_joint" pos="0 0 0" axis="0 1 0" />
          <geom type="mesh" rgba="0.898039 0.917647 0.929412 1" mesh="LF_calf_link" />
          <geom pos="0 0 -0.2136" quat="1 0 0 0" type="mesh" rgba="0.298039 0.298039 0.298039 1"
            mesh="LF_foot_link" />
        </body>
      </body>
    </body>
    <body name="RF_abad_link" pos="0.1941 -0.04 0">
      <inertial pos="-0.00266651 -0.013352 4.41572e-05"
        quat="0.70596 -0.00425428 -0.00526981 0.708219" mass="0.991879"
        diaginertia="0.00125474 0.000735477 0.000688757" />
      <joint name="RF_abad_joint" pos="0 0 0" axis="1 0 0" />
      <geom type="mesh" rgba="0.752941 0.752941 0.752941 1" mesh="RF_abad_link" />
      <body name="RF_hip_link" pos="0 -0.0666 0">
        <inertial pos="-0.00125357 -0.0194936 -0.0144608"
          quat="0.706238 -0.0180284 -0.00704616 0.70771" mass="1.29807"
          diaginertia="0.0028001 0.00204331 0.000920702" />
        <joint name="RF_hip_joint" pos="0 0 0" axis="0 1 0" />
        <geom type="mesh" rgba="0.752941 0.752941 0.752941 1" mesh="RF_hip_link" />
        <body name="RF_calf_link" pos="0 -0.0485 -0.213">
          <inertial pos="0.00999239 -7.40782e-08 -0.119966"
            quat="0.7067 0.0238402 0.0238413 0.70671" mass="0.494617"
            diaginertia="0.00267498 0.0026374 0.000100788" />
          <joint name="RF_calf_joint" pos="0 0 0" axis="0 1 0" />
          <geom type="mesh" rgba="0.647059 0.619608 0.588235 1" mesh="RF_calf_link" />
          <geom pos="0 0 -0.2136" quat="1 0 0 0" type="mesh" rgba="0.647059 0.619608 0.588235 1"
            mesh="RF_foot_link" />
        </body>
      </body>
    </body>
    <body name="RB_abad_link" pos="-0.1941 -0.04 0">
      <inertial pos="0.00266655 -0.013352 4.41673e-05" quat="0.708219 0.00527067 0.00425517 0.70596"
        mass="0.99188" diaginertia="0.00125474 0.000735478 0.000688757" />
      <joint name="RB_abad_joint" pos="0 0 0" axis="1 0 0" />
      <geom type="mesh" rgba="0.752941 0.752941 0.752941 1" mesh="RB_abad_link" />
      <body name="RB_hip_link" pos="0 -0.0666 0">
        <inertial pos="-0.00125357 -0.0194936 -0.0144608"
          quat="0.706238 -0.0180284 -0.00704616 0.70771" mass="1.29807"
          diaginertia="0.0028001 0.00204331 0.000920702" />
        <joint name="RB_hip_joint" pos="0 0 0" axis="0 1 0" />
        <geom type="mesh" rgba="0.752941 0.752941 0.752941 1" mesh="RB_hip_link" />
        <body name="RB_calf_link" pos="0 -0.0485 -0.213">
          <inertial pos="0.00999248 1.00894e-07 -0.119967"
            quat="0.706696 0.023841 0.0238376 0.706714" mass="0.494625"
            diaginertia="0.00267497 0.0026374 0.000100791" />
          <joint name="RB_calf_joint" pos="0 0 0" axis="0 1 0" />
          <geom type="mesh" rgba="0.647059 0.619608 0.588235 1" mesh="RB_calf_link" />
          <geom pos="0 0 -0.2136" quat="1 0 0 0" type="mesh" rgba="0.647059 0.619608 0.588235 1"
            mesh="RB_foot_link" />
        </body>
      </body>
    </body>
    <body name="LB_abad_link" pos="-0.1941 0.04 0">
      <inertial pos="0.00266651 0.013352 4.41572e-05" quat="0.70596 0.00425428 0.00526981 0.708219"
        mass="0.991879" diaginertia="0.00125474 0.000735477 0.000688757" />
      <joint name="LB_abad_joint" pos="0 0 0" axis="1 0 0" />
      <geom type="mesh" rgba="0.752941 0.752941 0.752941 1" mesh="LB_abad_link" />
      <body name="LB_hip_link" pos="0 0.0666 0">
        <inertial pos="-0.00125195 0.0194981 -0.0144633"
          quat="0.707714 -0.00704778 -0.0180221 0.706234" mass="1.29793"
          diaginertia="0.00279985 0.00204322 0.000920557" />
        <joint name="LB_hip_joint" pos="0 0 0" axis="0 1 0" />
        <geom type="mesh" rgba="0.752941 0.752941 0.752941 1" mesh="LB_hip_link" />
        <body name="LB_calf_link" pos="0 0.0485 -0.213">
          <inertial pos="0.00999239 -7.40876e-08 -0.119966"
            quat="0.7067 0.0238402 0.0238413 0.70671" mass="0.494617"
            diaginertia="0.00267498 0.0026374 0.000100788" />
          <joint name="LB_calf_joint" pos="0 0 0" axis="0 1 0" />
          <geom type="mesh" rgba="0.647059 0.619608 0.588235 1" mesh="LB_calf_link" />
          <geom pos="0 0 -0.2136" quat="1 0 0 0" type="mesh" rgba="0.647059 0.619608 0.588235 1"
            mesh="LB_foot_link" />
        </body>
      </body>
    </body>
  </worldbody>
</mujoco>